GLOB sdist-make: /home/madsilva/Devel/django-fitbit/setup.py
py36-1.11.X create: /home/madsilva/Devel/django-fitbit/.tox/py36-1.11.X
ERROR: InterpreterNotFound: python3.6
py36-docs create: /home/madsilva/Devel/django-fitbit/.tox/py36-docs
ERROR: InterpreterNotFound: python3.6
pypy-1.11.X create: /home/madsilva/Devel/django-fitbit/.tox/pypy-1.11.X
ERROR: InterpreterNotFound: pypy
pypy-1.10.X create: /home/madsilva/Devel/django-fitbit/.tox/pypy-1.10.X
ERROR: InterpreterNotFound: pypy
pypy-1.9.X create: /home/madsilva/Devel/django-fitbit/.tox/pypy-1.9.X
ERROR: InterpreterNotFound: pypy
py27-1.11.X inst-nodeps: /home/madsilva/Devel/django-fitbit/.tox/dist/django-fitbit-0.3.0.zip
py27-1.11.X installed: alabaster==0.7.10,amqp==2.2.2,Babel==2.5.1,billiard==3.5.0.3,celery==4.1.0,certifi==2017.7.27.1,chardet==3.0.4,coverage==4.4.1,Django==1.11.6,django-fitbit==0.3.0,docutils==0.14,fitbit==0.3.0,freezegun==0.3.9,funcsigs==1.0.2,idna==2.6,imagesize==0.7.1,Jinja2==2.9.6,kombu==4.1.0,MarkupSafe==1.0,mock==1.3.0,oauthlib==2.0.4,pbr==3.1.1,Pygments==2.2.0,python-dateutil==2.6.1,pytz==2017.2,requests==2.18.4,requests-mock==1.3.0,requests-oauthlib==0.8.0,simplejson==3.11.1,six==1.11.0,snowballstemmer==1.2.1,Sphinx==1.6.4,sphinxcontrib-websupport==1.0.1,typing==3.6.2,urllib3==1.22,vine==1.1.4
py27-1.11.X runtests: PYTHONHASHSEED='4157851322'
py27-1.11.X runtests: commands[0] | /home/madsilva/Devel/django-fitbit/.tox/py27-1.11.X/bin/python run_tests.py
.F..............................................................No handlers could be found for logger "fitapp.views"
.............................E...FFF.
======================================================================
ERROR: test_get_token_expired (fitapp.tests.test_integration.TestLogoutView)
----------------------------------------------------------------------
Traceback (most recent call last):
  File "/home/madsilva/Devel/django-fitbit/.tox/py27-1.11.X/local/lib/python2.7/site-packages/freezegun/api.py", line 495, in wrapper
    result = func(*args, **kwargs)
  File "/home/madsilva/Devel/django-fitbit/.tox/py27-1.11.X/local/lib/python2.7/site-packages/mock/mock.py", line 1305, in patched
    return func(*args, **keywargs)
  File "/home/madsilva/Devel/django-fitbit/fitapp/tests/test_integration.py", line 439, in test_get_token_expired
    assert mock_requests[1].path == '/1/user/-/apisubscriptions.json'
IndexError: list index out of range

======================================================================
FAIL: test_userfitbit (fitapp.tests.test_models.TestFitappModels)
UserFitbit was already created in base, now test the properties
----------------------------------------------------------------------
Traceback (most recent call last):
  File "/home/madsilva/Devel/django-fitbit/fitapp/tests/test_models.py", line 16, in test_userfitbit
    'user_id': self.fbuser.fitbit_user
AssertionError: {'refresh_token': 'FIcydWJtlHcIQxkouEeWsBYvr', 'uuid': 'wZ3jVOIKSci0lbBg_8xzMw', [truncated]... != {'refresh_token': 'FIcydWJtlHcIQxkouEeWsBYvr', 'refresh_cb': <bound method UserF [truncated]...
  {'access_token': 'FGDblFBnPRwACUUZucaNQsCFe',
   'expires_at': 1507576867.654203,
   'refresh_cb': <bound method UserFitbit.refresh_cb of <UserFitbit: TestUserModel object>>,
   'refresh_token': 'FIcydWJtlHcIQxkouEeWsBYvr',
-  'user_id': 'OzVRjZzjWqqggrHvsDKizohMw',
?                                        ^

+  'user_id': 'OzVRjZzjWqqggrHvsDKizohMw'}
?                                        ^

-  'uuid': 'wZ3jVOIKSci0lbBg_8xzMw'}

======================================================================
FAIL: test_subscribe (fitapp.tests.test_integration.TestSubscription)
----------------------------------------------------------------------
Traceback (most recent call last):
  File "/home/madsilva/Devel/django-fitbit/.tox/py27-1.11.X/local/lib/python2.7/site-packages/mock/mock.py", line 1305, in patched
    return func(*args, **keywargs)
  File "/home/madsilva/Devel/django-fitbit/fitapp/tests/test_integration.py", line 477, in test_subscribe
    collection=None)
  File "/home/madsilva/Devel/django-fitbit/.tox/py27-1.11.X/local/lib/python2.7/site-packages/mock/mock.py", line 948, in assert_called_once_with
    return self.assert_called_with(*args, **kwargs)
  File "/home/madsilva/Devel/django-fitbit/.tox/py27-1.11.X/local/lib/python2.7/site-packages/mock/mock.py", line 937, in assert_called_with
    six.raise_from(AssertionError(_error_message(cause)), cause)
  File "/home/madsilva/Devel/django-fitbit/.tox/py27-1.11.X/local/lib/python2.7/site-packages/six.py", line 737, in raise_from
    raise value
AssertionError: Expected call: subscription('2', '1', collection=None)
Actual call: subscription(u'GhKNkt7mQfuG-TMgB3K7YQ', '1', collection=None)

======================================================================
FAIL: test_subscribe_error (fitapp.tests.test_integration.TestSubscription)
----------------------------------------------------------------------
Traceback (most recent call last):
  File "/home/madsilva/Devel/django-fitbit/.tox/py27-1.11.X/local/lib/python2.7/site-packages/mock/mock.py", line 1305, in patched
    return func(*args, **keywargs)
  File "/home/madsilva/Devel/django-fitbit/fitapp/tests/test_integration.py", line 485, in test_subscribe_error
    collection=None)
  File "/home/madsilva/Devel/django-fitbit/.tox/py27-1.11.X/local/lib/python2.7/site-packages/mock/mock.py", line 948, in assert_called_once_with
    return self.assert_called_with(*args, **kwargs)
  File "/home/madsilva/Devel/django-fitbit/.tox/py27-1.11.X/local/lib/python2.7/site-packages/mock/mock.py", line 937, in assert_called_with
    six.raise_from(AssertionError(_error_message(cause)), cause)
  File "/home/madsilva/Devel/django-fitbit/.tox/py27-1.11.X/local/lib/python2.7/site-packages/six.py", line 737, in raise_from
    raise value
AssertionError: Expected call: subscription('2', '1', collection=None)
Actual call: subscription(u'Sq0hMGn7RhyuLT5jZ8bw3w', '1', collection=None)

======================================================================
FAIL: test_unsubscribe (fitapp.tests.test_integration.TestSubscription)
----------------------------------------------------------------------
Traceback (most recent call last):
  File "/home/madsilva/Devel/django-fitbit/.tox/py27-1.11.X/local/lib/python2.7/site-packages/mock/mock.py", line 1305, in patched
    return func(*args, **keywargs)
  File "/home/madsilva/Devel/django-fitbit/fitapp/tests/test_integration.py", line 501, in test_unsubscribe
    list_subscriptions.assert_called_once_with()
  File "/home/madsilva/Devel/django-fitbit/.tox/py27-1.11.X/local/lib/python2.7/site-packages/mock/mock.py", line 948, in assert_called_once_with
    return self.assert_called_with(*args, **kwargs)
  File "/home/madsilva/Devel/django-fitbit/.tox/py27-1.11.X/local/lib/python2.7/site-packages/mock/mock.py", line 937, in assert_called_with
    six.raise_from(AssertionError(_error_message(cause)), cause)
  File "/home/madsilva/Devel/django-fitbit/.tox/py27-1.11.X/local/lib/python2.7/site-packages/six.py", line 737, in raise_from
    raise value
AssertionError: Expected call: list_subscriptions()
Actual call: list_subscriptions(collection=None)

----------------------------------------------------------------------
Ran 101 tests in 22.205s

FAILED (failures=4, errors=1)
Creating test database for alias 'default'...
System check identified no issues (0 silenced).
Destroying test database for alias 'default'...
ERROR: InvocationError: '/home/madsilva/Devel/django-fitbit/.tox/py27-1.11.X/bin/python run_tests.py'
py27-1.10.X inst-nodeps: /home/madsilva/Devel/django-fitbit/.tox/dist/django-fitbit-0.3.0.zip
py27-1.10.X installed: alabaster==0.7.10,amqp==2.2.2,Babel==2.5.1,billiard==3.5.0.3,celery==4.1.0,certifi==2017.7.27.1,chardet==3.0.4,coverage==4.4.1,Django==1.10.8,django-fitbit==0.3.0,docutils==0.14,fitbit==0.3.0,freezegun==0.3.9,funcsigs==1.0.2,idna==2.6,imagesize==0.7.1,Jinja2==2.9.6,kombu==4.1.0,MarkupSafe==1.0,mock==1.3.0,oauthlib==2.0.4,pbr==3.1.1,Pygments==2.2.0,python-dateutil==2.6.1,pytz==2017.2,requests==2.18.4,requests-mock==1.3.0,requests-oauthlib==0.8.0,simplejson==3.11.1,six==1.11.0,snowballstemmer==1.2.1,Sphinx==1.6.4,sphinxcontrib-websupport==1.0.1,typing==3.6.2,urllib3==1.22,vine==1.1.4
py27-1.10.X runtests: PYTHONHASHSEED='4157851322'
py27-1.10.X runtests: commands[0] | /home/madsilva/Devel/django-fitbit/.tox/py27-1.10.X/bin/python run_tests.py
.F..............................................................No handlers could be found for logger "fitapp.views"
.............................E...FFF.
======================================================================
ERROR: test_get_token_expired (fitapp.tests.test_integration.TestLogoutView)
----------------------------------------------------------------------
Traceback (most recent call last):
  File "/home/madsilva/Devel/django-fitbit/.tox/py27-1.10.X/local/lib/python2.7/site-packages/freezegun/api.py", line 495, in wrapper
    result = func(*args, **kwargs)
  File "/home/madsilva/Devel/django-fitbit/.tox/py27-1.10.X/local/lib/python2.7/site-packages/mock/mock.py", line 1305, in patched
    return func(*args, **keywargs)
  File "/home/madsilva/Devel/django-fitbit/fitapp/tests/test_integration.py", line 439, in test_get_token_expired
    assert mock_requests[1].path == '/1/user/-/apisubscriptions.json'
IndexError: list index out of range

======================================================================
FAIL: test_userfitbit (fitapp.tests.test_models.TestFitappModels)
UserFitbit was already created in base, now test the properties
----------------------------------------------------------------------
Traceback (most recent call last):
  File "/home/madsilva/Devel/django-fitbit/fitapp/tests/test_models.py", line 16, in test_userfitbit
    'user_id': self.fbuser.fitbit_user
AssertionError: {'refresh_token': 'WDQCHSNhjSLcGibapZNCXvkNw', 'uuid': 'RlCxTE5VTcW7TgGtFPwzUQ', [truncated]... != {'refresh_token': 'WDQCHSNhjSLcGibapZNCXvkNw', 'refresh_cb': <bound method UserF [truncated]...
  {'access_token': 'RBekyMWuNeeUVENRZXmxhkHuA',
   'expires_at': 1507576893.306308,
   'refresh_cb': <bound method UserFitbit.refresh_cb of <UserFitbit: TestUserModel object>>,
   'refresh_token': 'WDQCHSNhjSLcGibapZNCXvkNw',
-  'user_id': 'kXWYHtHWYkWQPYroyFXJoyiIQ',
?                                        ^

+  'user_id': 'kXWYHtHWYkWQPYroyFXJoyiIQ'}
?                                        ^

-  'uuid': 'RlCxTE5VTcW7TgGtFPwzUQ'}

======================================================================
FAIL: test_subscribe (fitapp.tests.test_integration.TestSubscription)
----------------------------------------------------------------------
Traceback (most recent call last):
  File "/home/madsilva/Devel/django-fitbit/.tox/py27-1.10.X/local/lib/python2.7/site-packages/mock/mock.py", line 1305, in patched
    return func(*args, **keywargs)
  File "/home/madsilva/Devel/django-fitbit/fitapp/tests/test_integration.py", line 477, in test_subscribe
    collection=None)
  File "/home/madsilva/Devel/django-fitbit/.tox/py27-1.10.X/local/lib/python2.7/site-packages/mock/mock.py", line 948, in assert_called_once_with
    return self.assert_called_with(*args, **kwargs)
  File "/home/madsilva/Devel/django-fitbit/.tox/py27-1.10.X/local/lib/python2.7/site-packages/mock/mock.py", line 937, in assert_called_with
    six.raise_from(AssertionError(_error_message(cause)), cause)
  File "/home/madsilva/Devel/django-fitbit/.tox/py27-1.10.X/local/lib/python2.7/site-packages/six.py", line 737, in raise_from
    raise value
AssertionError: Expected call: subscription('2', '1', collection=None)
Actual call: subscription(u'u_-govIATzSOJNQbc6PbIw', '1', collection=None)

======================================================================
FAIL: test_subscribe_error (fitapp.tests.test_integration.TestSubscription)
----------------------------------------------------------------------
Traceback (most recent call last):
  File "/home/madsilva/Devel/django-fitbit/.tox/py27-1.10.X/local/lib/python2.7/site-packages/mock/mock.py", line 1305, in patched
    return func(*args, **keywargs)
  File "/home/madsilva/Devel/django-fitbit/fitapp/tests/test_integration.py", line 485, in test_subscribe_error
    collection=None)
  File "/home/madsilva/Devel/django-fitbit/.tox/py27-1.10.X/local/lib/python2.7/site-packages/mock/mock.py", line 948, in assert_called_once_with
    return self.assert_called_with(*args, **kwargs)
  File "/home/madsilva/Devel/django-fitbit/.tox/py27-1.10.X/local/lib/python2.7/site-packages/mock/mock.py", line 937, in assert_called_with
    six.raise_from(AssertionError(_error_message(cause)), cause)
  File "/home/madsilva/Devel/django-fitbit/.tox/py27-1.10.X/local/lib/python2.7/site-packages/six.py", line 737, in raise_from
    raise value
AssertionError: Expected call: subscription('2', '1', collection=None)
Actual call: subscription(u'ZnWiletuSQeUgUwf0wVvGw', '1', collection=None)

======================================================================
FAIL: test_unsubscribe (fitapp.tests.test_integration.TestSubscription)
----------------------------------------------------------------------
Traceback (most recent call last):
  File "/home/madsilva/Devel/django-fitbit/.tox/py27-1.10.X/local/lib/python2.7/site-packages/mock/mock.py", line 1305, in patched
    return func(*args, **keywargs)
  File "/home/madsilva/Devel/django-fitbit/fitapp/tests/test_integration.py", line 501, in test_unsubscribe
    list_subscriptions.assert_called_once_with()
  File "/home/madsilva/Devel/django-fitbit/.tox/py27-1.10.X/local/lib/python2.7/site-packages/mock/mock.py", line 948, in assert_called_once_with
    return self.assert_called_with(*args, **kwargs)
  File "/home/madsilva/Devel/django-fitbit/.tox/py27-1.10.X/local/lib/python2.7/site-packages/mock/mock.py", line 937, in assert_called_with
    six.raise_from(AssertionError(_error_message(cause)), cause)
  File "/home/madsilva/Devel/django-fitbit/.tox/py27-1.10.X/local/lib/python2.7/site-packages/six.py", line 737, in raise_from
    raise value
AssertionError: Expected call: list_subscriptions()
Actual call: list_subscriptions(collection=None)

----------------------------------------------------------------------
Ran 101 tests in 20.618s

FAILED (failures=4, errors=1)
Creating test database for alias 'default'...
Destroying test database for alias 'default'...
ERROR: InvocationError: '/home/madsilva/Devel/django-fitbit/.tox/py27-1.10.X/bin/python run_tests.py'
py27-1.9.X inst-nodeps: /home/madsilva/Devel/django-fitbit/.tox/dist/django-fitbit-0.3.0.zip
py27-1.9.X installed: alabaster==0.7.10,amqp==2.2.2,Babel==2.5.1,billiard==3.5.0.3,celery==4.1.0,certifi==2017.7.27.1,chardet==3.0.4,coverage==4.4.1,Django==1.9.13,django-fitbit==0.3.0,docutils==0.14,fitbit==0.3.0,freezegun==0.3.9,funcsigs==1.0.2,idna==2.6,imagesize==0.7.1,Jinja2==2.9.6,kombu==4.1.0,MarkupSafe==1.0,mock==1.3.0,oauthlib==2.0.4,pbr==3.1.1,Pygments==2.2.0,python-dateutil==2.6.1,pytz==2017.2,requests==2.18.4,requests-mock==1.3.0,requests-oauthlib==0.8.0,simplejson==3.11.1,six==1.11.0,snowballstemmer==1.2.1,Sphinx==1.6.4,sphinxcontrib-websupport==1.0.1,typing==3.6.2,urllib3==1.22,vine==1.1.4
py27-1.9.X runtests: PYTHONHASHSEED='4157851322'
py27-1.9.X runtests: commands[0] | /home/madsilva/Devel/django-fitbit/.tox/py27-1.9.X/bin/python run_tests.py
.F..............................................................No handlers could be found for logger "fitapp.views"
.............................E...FFF.
======================================================================
ERROR: test_get_token_expired (fitapp.tests.test_integration.TestLogoutView)
----------------------------------------------------------------------
Traceback (most recent call last):
  File "/home/madsilva/Devel/django-fitbit/.tox/py27-1.9.X/local/lib/python2.7/site-packages/freezegun/api.py", line 495, in wrapper
    result = func(*args, **kwargs)
  File "/home/madsilva/Devel/django-fitbit/.tox/py27-1.9.X/local/lib/python2.7/site-packages/mock/mock.py", line 1305, in patched
    return func(*args, **keywargs)
  File "/home/madsilva/Devel/django-fitbit/fitapp/tests/test_integration.py", line 439, in test_get_token_expired
    assert mock_requests[1].path == '/1/user/-/apisubscriptions.json'
IndexError: list index out of range

======================================================================
FAIL: test_userfitbit (fitapp.tests.test_models.TestFitappModels)
UserFitbit was already created in base, now test the properties
----------------------------------------------------------------------
Traceback (most recent call last):
  File "/home/madsilva/Devel/django-fitbit/fitapp/tests/test_models.py", line 16, in test_userfitbit
    'user_id': self.fbuser.fitbit_user
AssertionError: {'refresh_token': 'sDALHBmtdcuGFrwfaZaLkefRL', 'uuid': 'opZY77lCSkOk-pP2I7xFHw', [truncated]... != {'refresh_token': 'sDALHBmtdcuGFrwfaZaLkefRL', 'refresh_cb': <bound method UserF [truncated]...
  {'access_token': 'ktRmesXqluehyDZauxPyvvRMD',
   'expires_at': 1507576917.288295,
   'refresh_cb': <bound method UserFitbit.refresh_cb of <UserFitbit: TestUserModel object>>,
   'refresh_token': 'sDALHBmtdcuGFrwfaZaLkefRL',
-  'user_id': 'DoafelIiOsaunbMcVKrEKNYXR',
?                                        ^

+  'user_id': 'DoafelIiOsaunbMcVKrEKNYXR'}
?                                        ^

-  'uuid': 'opZY77lCSkOk-pP2I7xFHw'}

======================================================================
FAIL: test_subscribe (fitapp.tests.test_integration.TestSubscription)
----------------------------------------------------------------------
Traceback (most recent call last):
  File "/home/madsilva/Devel/django-fitbit/.tox/py27-1.9.X/local/lib/python2.7/site-packages/mock/mock.py", line 1305, in patched
    return func(*args, **keywargs)
  File "/home/madsilva/Devel/django-fitbit/fitapp/tests/test_integration.py", line 477, in test_subscribe
    collection=None)
  File "/home/madsilva/Devel/django-fitbit/.tox/py27-1.9.X/local/lib/python2.7/site-packages/mock/mock.py", line 948, in assert_called_once_with
    return self.assert_called_with(*args, **kwargs)
  File "/home/madsilva/Devel/django-fitbit/.tox/py27-1.9.X/local/lib/python2.7/site-packages/mock/mock.py", line 937, in assert_called_with
    six.raise_from(AssertionError(_error_message(cause)), cause)
  File "/home/madsilva/Devel/django-fitbit/.tox/py27-1.9.X/local/lib/python2.7/site-packages/six.py", line 737, in raise_from
    raise value
AssertionError: Expected call: subscription('2', '1', collection=None)
Actual call: subscription(u'tWKI7vznRMuNUPoDCHZCYw', '1', collection=None)

======================================================================
FAIL: test_subscribe_error (fitapp.tests.test_integration.TestSubscription)
----------------------------------------------------------------------
Traceback (most recent call last):
  File "/home/madsilva/Devel/django-fitbit/.tox/py27-1.9.X/local/lib/python2.7/site-packages/mock/mock.py", line 1305, in patched
    return func(*args, **keywargs)
  File "/home/madsilva/Devel/django-fitbit/fitapp/tests/test_integration.py", line 485, in test_subscribe_error
    collection=None)
  File "/home/madsilva/Devel/django-fitbit/.tox/py27-1.9.X/local/lib/python2.7/site-packages/mock/mock.py", line 948, in assert_called_once_with
    return self.assert_called_with(*args, **kwargs)
  File "/home/madsilva/Devel/django-fitbit/.tox/py27-1.9.X/local/lib/python2.7/site-packages/mock/mock.py", line 937, in assert_called_with
    six.raise_from(AssertionError(_error_message(cause)), cause)
  File "/home/madsilva/Devel/django-fitbit/.tox/py27-1.9.X/local/lib/python2.7/site-packages/six.py", line 737, in raise_from
    raise value
AssertionError: Expected call: subscription('2', '1', collection=None)
Actual call: subscription(u'u3mDqWmaSualmmWOaHBXHw', '1', collection=None)

======================================================================
FAIL: test_unsubscribe (fitapp.tests.test_integration.TestSubscription)
----------------------------------------------------------------------
Traceback (most recent call last):
  File "/home/madsilva/Devel/django-fitbit/.tox/py27-1.9.X/local/lib/python2.7/site-packages/mock/mock.py", line 1305, in patched
    return func(*args, **keywargs)
  File "/home/madsilva/Devel/django-fitbit/fitapp/tests/test_integration.py", line 501, in test_unsubscribe
    list_subscriptions.assert_called_once_with()
  File "/home/madsilva/Devel/django-fitbit/.tox/py27-1.9.X/local/lib/python2.7/site-packages/mock/mock.py", line 948, in assert_called_once_with
    return self.assert_called_with(*args, **kwargs)
  File "/home/madsilva/Devel/django-fitbit/.tox/py27-1.9.X/local/lib/python2.7/site-packages/mock/mock.py", line 937, in assert_called_with
    six.raise_from(AssertionError(_error_message(cause)), cause)
  File "/home/madsilva/Devel/django-fitbit/.tox/py27-1.9.X/local/lib/python2.7/site-packages/six.py", line 737, in raise_from
    raise value
AssertionError: Expected call: list_subscriptions()
Actual call: list_subscriptions(collection=None)

----------------------------------------------------------------------
Ran 101 tests in 23.920s

FAILED (failures=4, errors=1)
Creating test database for alias 'default'...
Destroying test database for alias 'default'...
ERROR: InvocationError: '/home/madsilva/Devel/django-fitbit/.tox/py27-1.9.X/bin/python run_tests.py'
py34-1.11.X create: /home/madsilva/Devel/django-fitbit/.tox/py34-1.11.X
ERROR: InterpreterNotFound: python3.4
py34-1.10.X create: /home/madsilva/Devel/django-fitbit/.tox/py34-1.10.X
ERROR: InterpreterNotFound: python3.4
py34-1.9.X create: /home/madsilva/Devel/django-fitbit/.tox/py34-1.9.X
ERROR: InterpreterNotFound: python3.4
py35-1.11.X inst-nodeps: /home/madsilva/Devel/django-fitbit/.tox/dist/django-fitbit-0.3.0.zip
py35-1.11.X installed: alabaster==0.7.10,amqp==2.2.2,Babel==2.5.1,billiard==3.5.0.3,celery==4.1.0,certifi==2017.7.27.1,chardet==3.0.4,coverage==4.4.1,Django==1.11.6,django-fitbit==0.3.0,docutils==0.14,fitbit==0.3.0,freezegun==0.3.9,idna==2.6,imagesize==0.7.1,Jinja2==2.9.6,kombu==4.1.0,MarkupSafe==1.0,mock==1.3.0,oauthlib==2.0.4,pbr==3.1.1,Pygments==2.2.0,python-dateutil==2.6.1,pytz==2017.2,requests==2.18.4,requests-mock==1.3.0,requests-oauthlib==0.8.0,simplejson==3.11.1,six==1.11.0,snowballstemmer==1.2.1,Sphinx==1.6.4,sphinxcontrib-websupport==1.0.1,urllib3==1.22,vine==1.1.4
py35-1.11.X runtests: PYTHONHASHSEED='4157851322'
py35-1.11.X runtests: commands[0] | /home/madsilva/Devel/django-fitbit/.tox/py35-1.11.X/bin/python run_tests.py
E
======================================================================
ERROR: fitapp.tests (unittest.loader._FailedTest)
----------------------------------------------------------------------
ImportError: Failed to import test module: fitapp.tests
Traceback (most recent call last):
  File "/usr/lib/python3.5/unittest/loader.py", line 462, in _find_test_path
    package = self._get_module_from_name(name)
  File "/usr/lib/python3.5/unittest/loader.py", line 369, in _get_module_from_name
    __import__(name)
  File "/home/madsilva/Devel/django-fitbit/fitapp/tests/__init__.py", line 4, in <module>
    from fitapp.tests.test_integration import *
  File "/home/madsilva/Devel/django-fitbit/fitapp/tests/test_integration.py", line 19, in <module>
    from test_models import TestUserModel
ImportError: No module named 'test_models'


----------------------------------------------------------------------
Ran 1 test in 0.001s

FAILED (errors=1)
Creating test database for alias 'default'...
System check identified no issues (0 silenced).
Destroying test database for alias 'default'...
ERROR: InvocationError: '/home/madsilva/Devel/django-fitbit/.tox/py35-1.11.X/bin/python run_tests.py'
py35-1.10.X inst-nodeps: /home/madsilva/Devel/django-fitbit/.tox/dist/django-fitbit-0.3.0.zip
py35-1.10.X installed: alabaster==0.7.10,amqp==2.2.2,Babel==2.5.1,billiard==3.5.0.3,celery==4.1.0,certifi==2017.7.27.1,chardet==3.0.4,coverage==4.4.1,Django==1.10.8,django-fitbit==0.3.0,docutils==0.14,fitbit==0.3.0,freezegun==0.3.9,idna==2.6,imagesize==0.7.1,Jinja2==2.9.6,kombu==4.1.0,MarkupSafe==1.0,mock==1.3.0,oauthlib==2.0.4,pbr==3.1.1,Pygments==2.2.0,python-dateutil==2.6.1,pytz==2017.2,requests==2.18.4,requests-mock==1.3.0,requests-oauthlib==0.8.0,simplejson==3.11.1,six==1.11.0,snowballstemmer==1.2.1,Sphinx==1.6.4,sphinxcontrib-websupport==1.0.1,urllib3==1.22,vine==1.1.4
py35-1.10.X runtests: PYTHONHASHSEED='4157851322'
py35-1.10.X runtests: commands[0] | /home/madsilva/Devel/django-fitbit/.tox/py35-1.10.X/bin/python run_tests.py
E
======================================================================
ERROR: fitapp.tests (unittest.loader._FailedTest)
----------------------------------------------------------------------
ImportError: Failed to import test module: fitapp.tests
Traceback (most recent call last):
  File "/usr/lib/python3.5/unittest/loader.py", line 462, in _find_test_path
    package = self._get_module_from_name(name)
  File "/usr/lib/python3.5/unittest/loader.py", line 369, in _get_module_from_name
    __import__(name)
  File "/home/madsilva/Devel/django-fitbit/fitapp/tests/__init__.py", line 4, in <module>
    from fitapp.tests.test_integration import *
  File "/home/madsilva/Devel/django-fitbit/fitapp/tests/test_integration.py", line 19, in <module>
    from test_models import TestUserModel
ImportError: No module named 'test_models'


----------------------------------------------------------------------
Ran 1 test in 0.000s

FAILED (errors=1)
Creating test database for alias 'default'...
Destroying test database for alias 'default'...
ERROR: InvocationError: '/home/madsilva/Devel/django-fitbit/.tox/py35-1.10.X/bin/python run_tests.py'
py35-1.9.X inst-nodeps: /home/madsilva/Devel/django-fitbit/.tox/dist/django-fitbit-0.3.0.zip
py35-1.9.X installed: alabaster==0.7.10,amqp==2.2.2,Babel==2.5.1,billiard==3.5.0.3,celery==4.1.0,certifi==2017.7.27.1,chardet==3.0.4,coverage==4.4.1,Django==1.9.13,django-fitbit==0.3.0,docutils==0.14,fitbit==0.3.0,freezegun==0.3.9,idna==2.6,imagesize==0.7.1,Jinja2==2.9.6,kombu==4.1.0,MarkupSafe==1.0,mock==1.3.0,oauthlib==2.0.4,pbr==3.1.1,Pygments==2.2.0,python-dateutil==2.6.1,pytz==2017.2,requests==2.18.4,requests-mock==1.3.0,requests-oauthlib==0.8.0,simplejson==3.11.1,six==1.11.0,snowballstemmer==1.2.1,Sphinx==1.6.4,sphinxcontrib-websupport==1.0.1,urllib3==1.22,vine==1.1.4
py35-1.9.X runtests: PYTHONHASHSEED='4157851322'
py35-1.9.X runtests: commands[0] | /home/madsilva/Devel/django-fitbit/.tox/py35-1.9.X/bin/python run_tests.py
E
======================================================================
ERROR: fitapp.tests (unittest.loader._FailedTest)
----------------------------------------------------------------------
ImportError: Failed to import test module: fitapp.tests
Traceback (most recent call last):
  File "/usr/lib/python3.5/unittest/loader.py", line 462, in _find_test_path
    package = self._get_module_from_name(name)
  File "/usr/lib/python3.5/unittest/loader.py", line 369, in _get_module_from_name
    __import__(name)
  File "/home/madsilva/Devel/django-fitbit/fitapp/tests/__init__.py", line 4, in <module>
    from fitapp.tests.test_integration import *
  File "/home/madsilva/Devel/django-fitbit/fitapp/tests/test_integration.py", line 19, in <module>
    from test_models import TestUserModel
ImportError: No module named 'test_models'


----------------------------------------------------------------------
Ran 1 test in 0.000s

FAILED (errors=1)
Creating test database for alias 'default'...
Destroying test database for alias 'default'...
ERROR: InvocationError: '/home/madsilva/Devel/django-fitbit/.tox/py35-1.9.X/bin/python run_tests.py'
pypy-1.8.X create: /home/madsilva/Devel/django-fitbit/.tox/pypy-1.8.X
ERROR: InterpreterNotFound: pypy
py27-1.8.X inst-nodeps: /home/madsilva/Devel/django-fitbit/.tox/dist/django-fitbit-0.3.0.zip
py27-1.8.X installed: alabaster==0.7.10,amqp==2.2.2,Babel==2.5.1,billiard==3.5.0.3,celery==4.1.0,certifi==2017.7.27.1,chardet==3.0.4,coverage==4.4.1,Django==1.8.18,django-fitbit==0.3.0,docutils==0.14,fitbit==0.3.0,freezegun==0.3.9,funcsigs==1.0.2,idna==2.6,imagesize==0.7.1,Jinja2==2.9.6,kombu==4.1.0,MarkupSafe==1.0,mock==1.3.0,oauthlib==2.0.4,pbr==3.1.1,Pygments==2.2.0,python-dateutil==2.6.1,pytz==2017.2,requests==2.18.4,requests-mock==1.3.0,requests-oauthlib==0.8.0,simplejson==3.11.1,six==1.11.0,snowballstemmer==1.2.1,Sphinx==1.6.4,sphinxcontrib-websupport==1.0.1,typing==3.6.2,urllib3==1.22,vine==1.1.4
py27-1.8.X runtests: PYTHONHASHSEED='4157851322'
py27-1.8.X runtests: commands[0] | /home/madsilva/Devel/django-fitbit/.tox/py27-1.8.X/bin/python run_tests.py
.F..............................................................No handlers could be found for logger "fitapp.views"
.............................E...FFF.
======================================================================
ERROR: test_get_token_expired (fitapp.tests.test_integration.TestLogoutView)
----------------------------------------------------------------------
Traceback (most recent call last):
  File "/home/madsilva/Devel/django-fitbit/.tox/py27-1.8.X/local/lib/python2.7/site-packages/freezegun/api.py", line 495, in wrapper
    result = func(*args, **kwargs)
  File "/home/madsilva/Devel/django-fitbit/.tox/py27-1.8.X/local/lib/python2.7/site-packages/mock/mock.py", line 1305, in patched
    return func(*args, **keywargs)
  File "/home/madsilva/Devel/django-fitbit/fitapp/tests/test_integration.py", line 439, in test_get_token_expired
    assert mock_requests[1].path == '/1/user/-/apisubscriptions.json'
IndexError: list index out of range

======================================================================
FAIL: test_userfitbit (fitapp.tests.test_models.TestFitappModels)
UserFitbit was already created in base, now test the properties
----------------------------------------------------------------------
Traceback (most recent call last):
  File "/home/madsilva/Devel/django-fitbit/fitapp/tests/test_models.py", line 16, in test_userfitbit
    'user_id': self.fbuser.fitbit_user
AssertionError: {'refresh_token': 'ZnTFxDMrRskZRoqWmIgnffVOk', 'uuid': 'SnkHvMNXRsabKfQSVRQrHw', [truncated]... != {'refresh_token': 'ZnTFxDMrRskZRoqWmIgnffVOk', 'refresh_cb': <bound method UserF [truncated]...
  {'access_token': 'WdmVMPupishUXLeDIIPkWoHsh',
   'expires_at': 1507576957.097874,
   'refresh_cb': <bound method UserFitbit.refresh_cb of <UserFitbit: TestUserModel object>>,
   'refresh_token': 'ZnTFxDMrRskZRoqWmIgnffVOk',
-  'user_id': 'ZgtQqXjfzKCSEvCtIctiVLRDU',
?                                        ^

+  'user_id': 'ZgtQqXjfzKCSEvCtIctiVLRDU'}
?                                        ^

-  'uuid': 'SnkHvMNXRsabKfQSVRQrHw'}

======================================================================
FAIL: test_subscribe (fitapp.tests.test_integration.TestSubscription)
----------------------------------------------------------------------
Traceback (most recent call last):
  File "/home/madsilva/Devel/django-fitbit/.tox/py27-1.8.X/local/lib/python2.7/site-packages/mock/mock.py", line 1305, in patched
    return func(*args, **keywargs)
  File "/home/madsilva/Devel/django-fitbit/fitapp/tests/test_integration.py", line 477, in test_subscribe
    collection=None)
  File "/home/madsilva/Devel/django-fitbit/.tox/py27-1.8.X/local/lib/python2.7/site-packages/mock/mock.py", line 948, in assert_called_once_with
    return self.assert_called_with(*args, **kwargs)
  File "/home/madsilva/Devel/django-fitbit/.tox/py27-1.8.X/local/lib/python2.7/site-packages/mock/mock.py", line 937, in assert_called_with
    six.raise_from(AssertionError(_error_message(cause)), cause)
  File "/home/madsilva/Devel/django-fitbit/.tox/py27-1.8.X/local/lib/python2.7/site-packages/six.py", line 737, in raise_from
    raise value
AssertionError: Expected call: subscription('2', '1', collection=None)
Actual call: subscription(u'F1qotTBASIWCWobTuvm9DQ', '1', collection=None)

======================================================================
FAIL: test_subscribe_error (fitapp.tests.test_integration.TestSubscription)
----------------------------------------------------------------------
Traceback (most recent call last):
  File "/home/madsilva/Devel/django-fitbit/.tox/py27-1.8.X/local/lib/python2.7/site-packages/mock/mock.py", line 1305, in patched
    return func(*args, **keywargs)
  File "/home/madsilva/Devel/django-fitbit/fitapp/tests/test_integration.py", line 485, in test_subscribe_error
    collection=None)
  File "/home/madsilva/Devel/django-fitbit/.tox/py27-1.8.X/local/lib/python2.7/site-packages/mock/mock.py", line 948, in assert_called_once_with
    return self.assert_called_with(*args, **kwargs)
  File "/home/madsilva/Devel/django-fitbit/.tox/py27-1.8.X/local/lib/python2.7/site-packages/mock/mock.py", line 937, in assert_called_with
    six.raise_from(AssertionError(_error_message(cause)), cause)
  File "/home/madsilva/Devel/django-fitbit/.tox/py27-1.8.X/local/lib/python2.7/site-packages/six.py", line 737, in raise_from
    raise value
AssertionError: Expected call: subscription('2', '1', collection=None)
Actual call: subscription(u'uH40CjtzRvWVbNbzRSDsFg', '1', collection=None)

======================================================================
FAIL: test_unsubscribe (fitapp.tests.test_integration.TestSubscription)
----------------------------------------------------------------------
Traceback (most recent call last):
  File "/home/madsilva/Devel/django-fitbit/.tox/py27-1.8.X/local/lib/python2.7/site-packages/mock/mock.py", line 1305, in patched
    return func(*args, **keywargs)
  File "/home/madsilva/Devel/django-fitbit/fitapp/tests/test_integration.py", line 501, in test_unsubscribe
    list_subscriptions.assert_called_once_with()
  File "/home/madsilva/Devel/django-fitbit/.tox/py27-1.8.X/local/lib/python2.7/site-packages/mock/mock.py", line 948, in assert_called_once_with
    return self.assert_called_with(*args, **kwargs)
  File "/home/madsilva/Devel/django-fitbit/.tox/py27-1.8.X/local/lib/python2.7/site-packages/mock/mock.py", line 937, in assert_called_with
    six.raise_from(AssertionError(_error_message(cause)), cause)
  File "/home/madsilva/Devel/django-fitbit/.tox/py27-1.8.X/local/lib/python2.7/site-packages/six.py", line 737, in raise_from
    raise value
AssertionError: Expected call: list_subscriptions()
Actual call: list_subscriptions(collection=None)

----------------------------------------------------------------------
Ran 101 tests in 21.309s

FAILED (failures=4, errors=1)
Creating test database for alias 'default'...
Destroying test database for alias 'default'...
ERROR: InvocationError: '/home/madsilva/Devel/django-fitbit/.tox/py27-1.8.X/bin/python run_tests.py'
py33-1.8.X create: /home/madsilva/Devel/django-fitbit/.tox/py33-1.8.X
ERROR: InterpreterNotFound: python3.3
py34-1.8.X create: /home/madsilva/Devel/django-fitbit/.tox/py34-1.8.X
ERROR: InterpreterNotFound: python3.4
___________________________________ summary ____________________________________
ERROR:   py36-1.11.X: InterpreterNotFound: python3.6
ERROR:   py36-docs: InterpreterNotFound: python3.6
ERROR:   pypy-1.11.X: InterpreterNotFound: pypy
ERROR:   pypy-1.10.X: InterpreterNotFound: pypy
ERROR:   pypy-1.9.X: InterpreterNotFound: pypy
ERROR:   py27-1.11.X: commands failed
ERROR:   py27-1.10.X: commands failed
ERROR:   py27-1.9.X: commands failed
ERROR:   py34-1.11.X: InterpreterNotFound: python3.4
ERROR:   py34-1.10.X: InterpreterNotFound: python3.4
ERROR:   py34-1.9.X: InterpreterNotFound: python3.4
ERROR:   py35-1.11.X: commands failed
ERROR:   py35-1.10.X: commands failed
ERROR:   py35-1.9.X: commands failed
ERROR:   pypy-1.8.X: InterpreterNotFound: pypy
ERROR:   py27-1.8.X: commands failed
ERROR:   py33-1.8.X: InterpreterNotFound: python3.3
ERROR:   py34-1.8.X: InterpreterNotFound: python3.4
